Workbook
Name Assistants: #REF!
Name Equipes: #REF!
Name Shift1: #REF!
Name Shift2: #REF!
Name Shift3: #REF!
Name Shift4: #REF!
Name Shift5: #REF!

Sheet Config
A2: 03 - Horaires Op Polyvalent Arrière.xlsx | B2: Op. poly arrière- | C2: Op. poly arrière-2026 | G2: Mise à jour horaire uniquement | L2: Mise à jour horaire par poste
A3: 04 - Horaires Op Fermentation.xlsx | B3: Op. éthanol (ferm.)- | C3: Op. éthanol (ferm.)-2026
A4: 05 - Horaires Op Distillation.xlsx | B4: Op. éthanol (dist.)- | C4: Op. éthanol (dist.)-2026
A5: 12 - Horaires Renforts.xlsx | B5: Renforts- | C5: Renforts-2026
A6: 06 - Horaires Op Meunerie.xlsx | B6: Meunerie- | C6: Meunerie-2026
A7: 07 - Horaires Op Gluten.xlsx | B7: Op. gluten- | C7: Op. gluten-2026
A8: 08 - Horaires Op Polyvalent Av.xlsx | B8: Op. poly av- | C8: Op. poly av-2026
A9: 09 - Horaires Op Polyvalent Avant.xlsx | B9: Op. poly avant- | C9: Op. poly avant-2026
A10: 10 - Horaires Op Centrale Thermique.xlsx | B10: Op. chaudière- | C10: Op. chaudière-2026 | G10: Modifications générales de la base de données
A11: B - Horaires Adjoints Contremaître.xlsx | B11: Adjoints- | C11: Adjoints-2026
A12: A - Horaires Contremaîtres de Production.xlsx | B12: Contremaîtres- | C12: Contremaîtres-2026
A13: 02 - Horaires Opérateurs en formation.xlsx | B13: Op. en formation- | C13: Op. en formation-2026
A14: 13 - Horaires Chaudières + renfort.xlsx | B14: Op. Chaudières+renfort- | C14: Op. Chaudières+renfort-2026
A15: 11 - Horaires Op STEP.xlsx | B15: Op. STEP- | C15: Op. STEP-2026
B18: Date de dernière mise à jour
B19: =Shift1!O2 -> 46295.595
A21: LIRE LES INSTRUCTIONS JUSQU'A LA FIN
A22: ATTENTION : pour les prochaines années, il faut que les lignes de 11 à 376 des 10 fichiers par fonction soient consacrées à l’horaire. En cas d’année avec 28j en février, la ligne 376 est vide
A23: Les lignes de 377 à 420 sont utilisées pour les compteurs;
A25: ATTENTION : les noms des onglets avec les horaires doivent correspondre à ceux marqués ci-dessus !! Attention aux espaces avant ou après les noms ci-dessous et sur les onglets !
A26: quand je crée le nouvel horaire, pas de barre d'espacement quand je renomme le nouvel onglet !!
A28: Au changement d'année :
A29: 1/ L'horaire Op Polyvalent Arrière doit être créer
A30: 2/ macro "mise à jour de l'année" :
A31: 3/ générer la mise à jour des noms puis l'horaire
A32: 4/ vérifier la compteurs en bas de page (cellules masquées et affichées)

Sheet Shift1
A1: SHIFT 1 | O1: Date de dernière mise à jour
O2: 46295.595
O4: VA | P4: Vacances annuelles | U4: xxx | V4: Congé accordé sous restriction - Rappelable | AB4: CP | AC4: Congé Parental
O5: RTT | P5: Récup. temps de travail | U5: R | V5: Remplacement | AB5: CSS | AC5: Congé sans solde
O6: RHS | P6: Récup. heures supplémentaires | U6: Abs, | V6: Absence - Maladie | AB6: R-CM | AC6: Remplacement Contremaître
O7: RJF | P7: Récup. Jour férié | U7: DS | V7: Délégation syndicale
C9: Adjoints Contremaître | O9: Polyvalent | Q9: Fermentation | S9: Distillation | U9: Renfort arrière | Y9: Meunerie | AA9: Gluten | AC9: Polyvalent | AE9: Polyvalent | AG9: Chaudières
C10: VGG | G10: JBI | I10: YBT | K10: ATR | M10: FPA | O10: DWS | Q10: APN | S10: GDT | U10: BBZ | Y10: TCE | AA10: NRD | AC10: CJD | AE10: HKB | AI10: KDN | AK10: PDF
B11: 1 | C11: - | G11: - | I11: AM | J11: Abs | K11: PM | L11: 8h -FT | M11: H. flott. | N11: 8h -FT | O11: N | Q11: N | S11: N | U11: N | V11: 8h -FT | Y11: N | AA11: PM | AE11: N | AG11: N | AI11: N | AJ11: RJF | AK11: N
B12: 2 | C12: H. flott | D12: RTT | G12: AM | H12: RHS | I12: PM | J12: Abs | K12: N | L12: R-CM | M12: H. flott. | N12: 4h RTT- | O12: - | Q12: - | S12: - | U12: - | Y12: - | AA12: N | AE12: - | AG12: - | AI12: - | AK12: -
A13: J | B13: 3 | C13: - | G13: AM | I13: PM | J13: Abs | K13: N | L13: R-CM | M13: - | N13: 4h RTT | O13: - | Q13: - | S13: - | U13: - | Y13: - | AA13: N | AE13: - | AG13: - | AI13: - | AK13: -
A14: A | B14: 4 | C14: - | G14: AM | H14: poly. Arr. | I14: PM | J14: Abs | K14: N | L14: R-CM | M14: - | O14: - | Q14: - | S14: - | U14: - | Y14: - | AA14: N | AE14: - | AG14: - | AI14: - | AK14: -
A15: N | B15: 5 | C15: H. flott. | G15: PM | H15: RTT - | I15: N | J15: Abs | K15: - | M15: AM | N15: R-CM | O15: 7h-15h | P15: TP | Q15: 6h-14h | S15: - | U15: 7h-15h | V15: VA | Y15: D | Z15: VA | AA15: - | AE15: - | AG15: 7h-15h | AI15: - | AK15: -
A16: V | B16: 6 | C16: H. flott. | D16: 1h RHS | G16: PM | H16: poly. Arr. | I16: N | J16: Abs | K16: - | M16: AM | N16: R-CM | O16: 7h-15h | P16: TP | Q16: 6h-14h | R16: Abs | S16: 6h-14h | T16: 2h RTT- | U16: 7h-15h | V16: VA | Y16: D | Z16: VA | AA16: - | AE16: - | AG16: 7h-15h | AI16: - | AK16: -
A17: I | B17: 7 | C17: H. flott. | D17: R-CM | G17: N | H17: R-CM | I17: - | J17: Abs | K17: R-CM | L17: 2h RTT- | M17: PM | N17: R-CM | O17: 7h-15h | P17: 4h RTT | Q17: 6h-14h | R17: Abs | S17: 6h-14h | T17: 2h RTT- | U17: 7h-15h | V17: VA | Y17: D | Z17: R | AA17: AM | AE17: 6h-14h | AG17: 7h-15h | AI17: 6h-14h | AJ17: CP | AK17: 6h-14h | AL17: R
A18: E | B18: 8 | C18: H. flott. | D18: R-CM | G18: N | H18: R-CM | I18: - | J18: Abs | K18: AM | L18: VA | M18: PM | N18: R-CM | O18: - | Q18: - | R18: Abs | S18: 6h-14h | T18: - | U18: - | Y18: - | AA18: AM | AB18: 2h RTT | AE18: 6h-14h | AG18: - | AI18: 6h-14h | AJ18: CP | AK18: 6h-14h | AL18: VA
A19: R | B19: 9 | C19: H. flott. | D19: RJF | G19: - | I19: AM | J19: Abs | K19: PM | L19: R-CM | M19: N | N19: R-CM | O19: - | Q19: - | R19: Abs | S19: 6h-14h | T19: RTT- | U19: - | Y19: - | AA19: PM | AB19: 2h RTT | AE19: 6h-14h | AG19: - | AI19: 6h-14h | AJ19: VA | AK19: 6h-14h
B20: 10 | C20: - | G20: - | H20: 4h +FT | I20: AM | J20: Abs | K20: PM | L20: R-CM | M20: N | N20: R-CM | O20: - | Q20: - | R20: Abs | S20: - | U20: - | Y20: - | AA20: PM | AE20: - | AG20: - | AI20: - | AK20: -
B21: 11 | C21: - | G21: - | I21: AM | J21: Abs | K21: PM | L21: R-CM | M21: N | N21: R-CM | O21: - | Q21: - | R21: Abs | S21: - | U21: - | Y21: - | AA21: PM | AE21: - | AG21: - | AI21: - | AK21: -
B22: 12 | C22: AM | D22: poly-arr | G22: AM | H22: R-CM | I22: PM | J22: Abs | K22: N | M22: - | O22: AM | P22: chaudières | Q22: AM | R22: Abs | S22: AM | U22: AM | Y22: AM | AA22: N | AC22: D | AE22: AM | AG22: AM | AI22: AM | AK22: AM | AL22: F
B23: 13 | C23: AM | D23: Abs | G23: 7h-15h | H23: 1h rhs | I23: PM | J23: Abs | K23: N | L23: R-CM | M23: - | N23: 2h +FT | O23: AM | Q23: AM | R23: Abs | S23: AM | U23: AM | Y23: AM | AA23: N | AC23: D | AE23: AM | AG23: AM | AI23: AM | AK23: AM
A24: 2 | B24: 14 | C24: PM | D24: Abs | G24: 14h-01h | H24: R-CM | I24: PM | J24: Abs | K24: - | M24: AM | N24: R-CM | O24: F | P24: 2h +FT | Q24: PM | S24: terr. Arr. | T24: 2h RTT | U24: PM | V24: R | Y24: PM | AA24: - | AC24: D | AE24: PM | AF24: N | AG24: PM | AI24: PM | AJ24: N | AK24: PM
A25: 0 | B25: 15 | C25: PM | D25: Abs | G25: PM | H25: R-CM | I25: N | J25: Abs | K25: - | M25: AM | N25: R-CM | O25: AM | P25: 3h RTT | Q25: PM | S25: PM | T25: AM | U25: PM | V25: R | Y25: PM | AA25: - | AC25: D | AE25: PM | AF25: N | AG25: PM | AI25: PM | AK25: D-F | AL25: 2h RTT
A26: 2 | B26: 16 | C26: N | D26: Abs | G26: - | H26: 3h +FT | I26: - | J26: Abs | K26: AM | L26: R-CM | M26: PM | N26: R-CM | O26: N | P26: Abs | Q26: N | S26: N | T26: terr. Arr. | U26: N | V26: R | Y26: N | AA26: AM | AC26: D | AE26: N | AG26: N | AI26: N | AK26: N
A27: 6 | B27: 17 | C27: N | D27: Abs | G27: - | H27: 18h-22h | I27: - | J27: Abs | K27: AM | L27: R-CM | M27: PM | N27: 8h -FT | O27: N | P27: Abs | Q27: N | S27: N | T27: terr. Arr. | U27: N | V27: R | Y27: N | AA27: AM | AC27: - | AE27: N | AG27: N | AI27: N | AK27: N
B28: 18 | C28: N | D28: Abs | G28: - | I28: - | J28: Abs | K28: AM | L28: R-CM | M28: PM | N28: Abs | O28: N | P28: Abs | Q28: N | S28: N | T28: terr. Arr. | U28: N | V28: R | Y28: N | AA28: AM | AC28: - | AE28: N | AG28: N | AI28: N | AK28: N
B29: 19 | C29: - | G29: AM | H29: R-CM | I29: D | J29: Abs | K29: PM | M29: N | N29: Abs | O29: - | P29: Abs | Q29: - | S29: - | U29: - | Y29: - | AA29: PM | AC29: D | AE29: - | AG29: - | AI29: - | AK29: -
B30: 20 | C30: - | G30: AM | H30: R-CM | I30: D | J30: Abs | K30: PM | L30: meunerie | M30: N | N30: Abs | O30: - | P30: Abs | Q30: - | S30: - | U30: - | Y30: - | AA30: PM | AC30: D | AD30: 4h RTT | AE30: - | AG30: - | AI30: - | AK30: -
B31: 21 | C31: AM | D31: R-CM | G31: 7h-15h | H31: F | I31: D | J31: Abs | K31: N | L31: DS-CE | M31: N | N31: Abs | O31: AM | P31: Abs | Q31: AM | S31: AM | T31: terr. Arr. | U31: AM | V31: R | Y31: AM | AA31: N | AB31: Abs | AC31: D | AE31: AM | AG31: AM | AI31: AM | AJ31: F | AK31: AM
B32: 22 | C32: PM | D32: R-CM | G32: 7h-15h | H32: 3h rhs | I32: - | J32: Abs | K32: AM | L32: R-CM | M32: - | N32: Abs | O32: AM | P32: Abs | Q32: AM | S32: AM | T32: terr. Arr. | U32: AM | V32: R | Y32: AM | AA32: N | AB32: Abs | AC32: D | AE32: AM | AG32: AM | AI32: AM | AJ32: 06h-18h | AK32: AM
B33: 23 | C33: PM | D33: VA | G33: 7h-15h | H33: F | I33: - | J33: Abs | K33: - | M33: AM | N33: Abs | O33: PM | P33: Abs | Q33: PM | R33: 1/2VA | S33: PM | T33: terr. Arr. | U33: PM | V33: R | Y33: PM | AA33: - | AC33: D | AE33: PM | AG33: PM | AI33: PM | AK33: PM
B34: 24 | C34: PM | D34: VA | G34: - | I34: - | J34: Abs | K34: - | L34: 2h RTT | M34: AM | N34: Abs | O34: PM | P34: Abs | Q34: PM | S34: PM | T34: terr. Arr. | U34: PM | V34: RJF | Y34: PM | AA34: - | AC34: - | AE34: PM | AG34: PM | AI34: PM | AJ34: VA | AK34: PM
B35: 25 | C35: PM | D35: VA | G35: - | I35: - | J35: Abs | K35: - | M35: PM | N35: Abs | O35: PM | P35: Abs | Q35: PM | S35: PM | T35: AM | U35: PM | V35: R | Y35: PM | AA35: 10h-22h | AB35: 4h +FT | AC35: - | AE35: PM | AF35: 4h -FT | AG35: PM | AI35: PM | AJ35: 18h-06h | AK35: PM | AL35: VA
B36: 26 | C36: N | D36: R-CM | G36: AM | H36: poly. Arr. | I36: D | J36: Abs | K36: 7h-15h | L36: F | M36: PM | N36: Abs | O36: N | P36: Abs | Q36: N | S36: N | T36: terr. Arr. | U36: N | V36: R | Y36: N | AA36: N | AB36: VA | AC36: D | AE36: N | AG36: N | AI36: N | AK36: N | AL36: F
B37: 27 | C37: N | D37: 4h RTT | G37: AM | H37: RHS | I37: D | J37: Abs | K37: 7h-15h | L37: F | M37: PM | N37: Abs | O37: N | P37: Abs | Q37: N | R37: R | S37: N | T37: terr. Arr. | U37: N | V37: R | Y37: N | AA37: N | AC37: D | AE37: N | AG37: N | AI37: N | AK37: N | AL37: F
B38: 28 | C38: - | G38: PM | H38: RHS | I38: D | J38: Abs | K38: 7h-15h | L38: R | M38: N | N38: Abs | O38: - | P38: Abs | Q38: - | S38: - | U38: - | Y38: - | AA38: - | AC38: D | AE38: - | AG38: - | AI38: - | AK38: - | AL38: F
B39: 29 | C39: - | G39: PM | H39: VA | I39: D | J39: Abs | K39: - | M39: N | N39: Abs | O39: - | P39: Abs | Q39: - | S39: - | U39: - | Y39: - | AA39: - | AC39: D | AE39: - | AG39: - | AI39: - | AK39: -
B40: 30 | C40: AM | D40: Abs | G40: 18h-06h | H40: R-CM | I40: D | J40: Abs | K40: - | M40: - | N40: Abs | O40: AM | P40: Abs | Q40: AM | S40: AM | T40: terr. Arr. | U40: AM | V40: R | Y40: AM | AA40: AM | AB40: PM | AC40: D | AE40: AM | AF40: N | AG40: AM | AI40: AM | AK40: AM | AL40: -
B41: 31 | C41: R-CM | D41: 06h-16h | G41: N | H41: 19h-22h | I41: - | J41: Abs | K41: - | M41: - | N41: Abs | O41: AM | P41: Abs | Q41: AM | R41: PM | S41: AM | T41: Abs | U41: AM | V41: R | Y41: AM | AA41: AM | AB41: PM | AC41: - | AE41: AM | AF41: N | AG41: AM | AI41: AM | AK41: AM
B42: 1 | C42: AM | D42: R-CM | G42: N | H42: poly-arr | I42: - | J42: Abs | K42: - | M42: - | N42: Abs | O42: AM | P42: Abs | Q42: AM | R42: PM | S42: terr. Arr. | T42: Abs | U42: AM | V42: R | Y42: AM | AA42: AM | AB42: PM | AC42: - | AE42: N | AF42: 1h -FT | AG42: AM | AI42: AM | AJ42: RJF | AK42: AM
...

Sheet Shift2
A1: SHIFT 2 | O1: Date de dernière mise à jour
O2: =Shift1!O2 -> 46295.595
O4: VA | P4: Vacances annuelles | U4: xxx | V4: Congé accordé sous restriction - Rappelable | AB4: CP | AC4: Congé Parental
O5: RTT | P5: Récup. temps de travail | U5: R | V5: Remplacement | AB5: CSS | AC5: Congé sans solde
O6: RHS | P6: Récup. heures supplémentaires | U6: Abs, | V6: Absence - Maladie | AB6: R-CM | AC6: Remplacement Contremaître
O7: RJF | P7: Récup. Jour férié | U7: DS | V7: Délégation syndicale
C9: Adjoints Contremaître | O9: Polyvalent | Q9: Fermentation | S9: Distillation | U9: Renfort avant | W9: Renfort avant | Y9: Meunerie | AA9: Gluten | AC9: Polyvalent | AE9: Polyvalent | AG9: Chaudières | AM9: Renfort arrière
C10: VGG | G10: JBI | I10: YBT | K10: ATR | M10: FPA | O10: SBZ | Q10: LAA | S10: NPE | U10: DBE | W10: YRS | Y10: BLR | AA10: CWN | AC10: JKS | AE10: ASS | AG10: GJR | AI10: ADS | AK10: QDE | AM10: GKT
B11: 1 | C11: - | G11: - | I11: AM | J11: Abs | K11: PM | L11: 8h -FT | M11: H. flott. | N11: 8h -FT | O11: AM | Q11: AM | S11: AM | U11: AM | V11: N | W11: D | X11: RJF | Y11: AM | Z11: PM | AA11: AM | AB11: RJF | AC11: AM | AE11: AM | AG11: AM | AH11: 8h -FT | AI11: N | AK11: AM | AM11: -
B12: 2 | C12: H. flott | D12: RTT | G12: AM | H12: RHS | I12: PM | J12: Abs | K12: N | L12: R-CM | M12: H. flott. | N12: 4h RTT- | O12: PM | Q12: PM | R12: N | S12: PM | U12: PM | W12: D | X12: 2h RTT- | Y12: PM | AA12: PM | AC12: PM | AD12: AM | AE12: PM | AF12: DTT | AG12: PM | AH12: VA | AI12: - | AK12: PM | AM12: AM | AN12: R
A13: J | B13: 3 | C13: - | G13: AM | I13: PM | J13: Abs | K13: N | L13: R-CM | M13: - | N13: 4h RTT | O13: PM | Q13: PM | R13: N | S13: PM | U13: PM | W13: - | Y13: PM | AA13: PM | AC13: PM | AE13: PM | AG13: PM | AI13: - | AK13: PM | AL13: RJF | AM13: AM | AN13: VA
A14: A | B14: 4 | C14: - | G14: AM | H14: poly. Arr. | I14: PM | J14: Abs | K14: N | L14: R-CM | M14: - | O14: PM | Q14: PM | R14: N | S14: PM | U14: PM | W14: - | Y14: PM | AA14: PM | AC14: PM | AE14: PM | AG14: PM | AI14: - | AK14: PM | AL14: RJF | AM14: AM | AN14: R
A15: N | B15: 5 | C15: H. flott. | G15: PM | H15: RTT - | I15: N | J15: Abs | K15: - | M15: AM | N15: R-CM | O15: N | Q15: N | S15: N | U15: N | W15: D | Y15: N | Z15: VA | AA15: N | AB15: PM | AC15: N | AD15: RTT- | AE15: N | AF15: PM | AG15: N | AI15: D | AJ15: CP | AK15: N | AL15: RJF | AM15: PM | AN15: R
A16: V | B16: 6 | C16: H. flott. | D16: 1h RHS | G16: PM | H16: poly. Arr. | I16: N | J16: Abs | K16: - | M16: AM | N16: R-CM | O16: N | P16: CT | Q16: N | R16: VA | S16: N | U16: N | W16: D | Y16: N | AA16: N | AB16: PM | AC16: N | AD16: RTT- | AE16: PM | AF16: 4h RHS | AG16: N | AI16: D | AJ16: CP | AK16: N | AL16: RJF | AM16: PM | AN16: R
A17: I | B17: 7 | C17: H. flott. | D17: R-CM | G17: N | H17: R-CM | I17: - | J17: Abs | K17: R-CM | L17: 2h RTT- | M17: PM | N17: R-CM | O17: - | Q17: - | S17: - | U17: - | W17: D | X17: 3h RTT- | Y17: - | AA17: - | AC17: - | AE17: - | AF17: PM | AG17: - | AI17: D | AJ17: CP | AK17: - | AM17: N | AN17: R
A18: E | B18: 8 | C18: H. flott. | D18: R-CM | G18: N | H18: R-CM | I18: - | J18: Abs | K18: AM | L18: VA | M18: PM | N18: R-CM | O18: - | Q18: - | S18: - | U18: - | W18: D | Y18: - | AA18: - | AC18: - | AE18: - | AG18: - | AI18: - | AK18: - | AM18: N | AN18: R
A19: R | B19: 9 | C19: H. flott. | D19: RJF | G19: - | I19: AM | J19: Abs | K19: PM | L19: R-CM | M19: N | N19: R-CM | O19: AM | P19: 3 RTT- | Q19: AM | S19: AM | U19: AM | W19: D | Y19: AM | Z19: PM | AA19: AM | AC19: AM | AD19: RTT- | AE19: AM | AF19: DTT | AG19: AM | AI19: - | AK19: AM | AL19: RJF | AM19: -
B20: 10 | C20: - | G20: - | H20: 4h +FT | I20: AM | J20: Abs | K20: PM | L20: R-CM | M20: N | N20: R-CM | O20: AM | P20: 2h RTT- | Q20: AM | S20: AM | U20: AM | W20: - | Y20: AM | Z20: PM | AA20: AM | AC20: AM | AE20: AM | AG20: AM | AI20: - | AK20: AM | AL20: RJF | AM20: -
B21: 11 | C21: - | G21: - | I21: AM | J21: Abs | K21: PM | L21: R-CM | M21: N | N21: R-CM | O21: AM | Q21: AM | S21: AM | T21: PM | U21: AM | W21: - | Y21: AM | Z21: PM | AA21: AM | AC21: AM | AE21: AM | AF21: 8h -FT | AG21: AM | AI21: - | AK21: AM | AM21: -
B22: 12 | C22: AM | D22: poly-arr | G22: AM | H22: R-CM | I22: PM | J22: Abs | K22: N | M22: - | O22: PM | P22: Abs | Q22: N | R22: RTT | S22: PM | U22: PM | W22: D | X22: 1h -FT | Y22: PM | AA22: PM | AB22: F | AC22: PM | AE22: PM | AG22: PM | AI22: AM | AJ22: Abs | AK22: PM | AM22: D | AN22: VA
B23: 13 | C23: AM | D23: Abs | G23: 7h-15h | H23: 1h rhs | I23: PM | J23: Abs | K23: N | L23: R-CM | M23: - | N23: 2h +FT | O23: PM | P23: Abs | Q23: PM | R23: N | S23: PM | U23: PM | W23: D | Y23: PM | AA23: PM | AC23: PM | AE23: PM | AG23: PM | AI23: AM | AJ23: Abs | AK23: PM | AM23: D | AN23: VA
A24: 2 | B24: 14 | C24: PM | D24: Abs | G24: 14h-01h | H24: R-CM | I24: PM | J24: Abs | K24: - | M24: AM | N24: R-CM | O24: N | P24: Abs | Q24: N | S24: N | U24: N | W24: D | Y24: N | AA24: N | AB24: PM | AC24: PM | AD24: F | AE24: N | AG24: N | AI24: PM | AJ24: Abs | AK24: PM | AL24: F | AM24: D | AN24: VA
A25: 0 | B25: 15 | C25: PM | D25: Abs | G25: PM | H25: R-CM | I25: N | J25: Abs | K25: - | M25: AM | N25: R-CM | O25: N | P25: Abs | Q25: N | S25: N | U25: N | W25: D | Y25: N | AA25: N | AB25: PM | AC25: N | AD25: PM | AE25: N | AG25: N | AI25: PM | AJ25: Abs | AK25: N | AM25: -
A26: 2 | B26: 16 | C26: N | D26: Abs | G26: - | H26: 3h +FT | I26: - | J26: Abs | K26: AM | L26: R-CM | M26: PM | N26: R-CM | O26: - | P26: Abs | Q26: - | S26: - | U26: - | W26: D | X26: RHS | Y26: - | AA26: - | AC26: - | AE26: - | AG26: - | AI26: N | AJ26: Abs | AK26: - | AM26: -
A27: 6 | B27: 17 | C27: N | D27: Abs | G27: - | H27: 18h-22h | I27: - | J27: Abs | K27: AM | L27: R-CM | M27: PM | N27: 8h -FT | O27: - | Q27: - | S27: - | U27: - | W27: - | Y27: - | AA27: - | AC27: - | AE27: - | AG27: - | AI27: N | AJ27: Abs | AK27: - | AM27: -
B28: 18 | C28: N | D28: Abs | G28: - | I28: - | J28: Abs | K28: AM | L28: R-CM | M28: PM | N28: Abs | O28: - | Q28: - | S28: - | U28: - | W28: - | Y28: - | AA28: - | AC28: - | AE28: - | AG28: - | AI28: N | AJ28: Abs | AK28: - | AM28: -
B29: 19 | C29: - | G29: AM | H29: R-CM | I29: D | J29: Abs | K29: PM | M29: N | N29: Abs | O29: - | Q29: - | S29: 6h-14h | U29: 6h-14h | W29: D | Y29: - | AA29: - | AC29: 6h-14h | AE29: 6h-14h | AF29: RJF | AG29: - | AI29: - | AK29: - | AM29: AM | AN29: 4h RTT
B30: 20 | C30: - | G30: AM | H30: R-CM | I30: D | J30: Abs | K30: PM | L30: meunerie | M30: N | N30: Abs | O30: - | Q30: - | S30: 6h-14h | U30: 6h-14h | W30: D | Y30: - | AA30: D | AB30: STEP | AC30: 6h-14h | AD30: DS | AE30: 6h-14h | AF30: RHS | AG30: - | AI30: - | AK30: - | AM30: AM | AN30: terr. Arr.
B31: 21 | C31: AM | D31: R-CM | G31: 7h-15h | H31: F | I31: D | J31: Abs | K31: N | L31: DS-CE | M31: N | N31: Abs | O31: D | P31: CT | Q31: D | R31: F | S31: 6h-14h | U31: 6h-14h | W31: D | Y31: - | Z31: 7h-15h | AA31: D | AB31: CP | AC31: 6h-14h | AD31: DS | AE31: 6h-14h | AF31: RHS | AG31: 6h-14h | AH31: VA | AI31: AM | AK31: 7h-15h | AL31: 6h-14h | AM31: PM | AN31: terr. Arr.
B32: 22 | C32: PM | D32: R-CM | G32: 7h-15h | H32: 3h rhs | I32: - | J32: Abs | K32: AM | L32: R-CM | M32: - | N32: Abs | O32: D | P32: CT | Q32: D | R32: VA | S32: - | U32: - | W32: D | Y32: D | Z32: 7h-15h | AA32: D | AB32: CP | AC32: - | AE32: - | AG32: 6h-14h | AH32: RTT | AI32: AM | AK32: 7h-15h | AM32: PM | AN32: R
B33: 23 | C33: PM | D33: VA | G33: 7h-15h | H33: F | I33: - | J33: Abs | K33: - | M33: AM | N33: Abs | O33: D | P33: CT | Q33: D | R33: VA | S33: - | U33: - | W33: D | Y33: D | Z33: - | AA33: D | AB33: - | AC33: AM | AD33: Ferm. Liq. | AE33: - | AG33: 6h-14h | AH33: RTT | AI33: PM | AK33: 7h-15h | AM33: N | AN33: R
B34: 24 | C34: PM | D34: VA | G34: - | I34: - | J34: Abs | K34: - | L34: 2h RTT | M34: AM | N34: Abs | O34: - | Q34: - | S34: PM | T34: 8h +FT | U34: - | W34: - | Y34: - | AA34: - | AC34: - | AE34: - | AG34: - | AI34: PM | AK34: - | AM34: N | AN34: poly-arr
B35: 25 | C35: PM | D35: VA | G35: - | I35: - | J35: Abs | K35: - | M35: PM | N35: Abs | O35: - | Q35: - | S35: - | U35: - | W35: - | Y35: - | AA35: - | AC35: - | AE35: - | AG35: - | AI35: PM | AK35: - | AM35: N
B36: 26 | C36: N | D36: R-CM | G36: AM | H36: poly. Arr. | I36: D | J36: Abs | K36: 7h-15h | L36: F | M36: PM | N36: Abs | O36: AM | P36: F | Q36: AM | R36: F | S36: AM | U36: AM | W36: AM | Y36: D | AA36: AM | AB36: F | AC36: AM | AD36: PM | AE36: AM | AF36: DTT | AG36: AM | AH36: Abs | AI36: N | AK36: AM | AL36: 2h -FT | AM36: -
B37: 27 | C37: N | D37: 4h RTT | G37: AM | H37: RHS | I37: D | J37: Abs | K37: 7h-15h | L37: F | M37: PM | N37: Abs | O37: AM | P37: F | Q37: AM | R37: F | S37: AM | U37: AM | W37: AM | Y37: D | AA37: AM | AB37: F | AC37: AM | AD37: PM | AE37: AM | AF37: DTT | AG37: AM | AI37: N | AK37: AM | AM37: -
B38: 28 | C38: - | G38: PM | H38: RHS | I38: D | J38: Abs | K38: 7h-15h | L38: R | M38: N | N38: Abs | O38: PM | Q38: PM | R38: F | S38: PM | U38: PM | W38: PM | Y38: D | AA38: PM | AB38: F | AC38: 10h-22h | AD38: 4h +FT | AE38: PM | AF38: 2h rhs | AG38: AM | AH38: Abs | AI38: - | AK38: PM | AM38: AM | AN38: distillation
B39: 29 | C39: - | G39: PM | H39: VA | I39: D | J39: Abs | K39: - | M39: N | N39: Abs | O39: PM | P39: R | Q39: PM | S39: PM | U39: PM | W39: PM | X39: N | Y39: D | AA39: 10h-22h | AB39: 4h +FT | AC39: PM | AD39: meunerie | AE39: PM | AF39: 3h rhs | AG39: AM | AH39: Abs | AI39: - | AK39: PM | AM39: AM | AN39: distillation
B40: 30 | C40: AM | D40: Abs | G40: 18h-06h | H40: R-CM | I40: D | J40: Abs | K40: - | M40: - | N40: Abs | O40: N | Q40: N | R40: VA | S40: N | U40: N | V40: AM | W40: N | Y40: D | AA40: N | AB40: AM | AC40: N | AD40: PM | AE40: N | AF40: PM | AG40: N | AH40: Abs | AJ40: AM | AK40: N | AM40: PM | AN40: VA
B41: 31 | C41: R-CM | D41: 06h-16h | G41: N | H41: 19h-22h | I41: - | J41: Abs | K41: - | M41: - | N41: Abs | O41: N | Q41: N | S41: N | U41: N | V41: AM | W41: N | Y41: - | AA41: N | AB41: AM | AC41: PM | AD41: 3h -FT | AE41: N | AF41: PM | AG41: N | AH41: Abs | AJ41: AM | AK41: N | AM41: PM
B42: 1 | C42: AM | D42: R-CM | G42: N | H42: poly-arr | I42: - | J42: Abs | K42: - | M42: - | N42: Abs | O42: N | P42: CT | Q42: N | S42: N | U42: N | V42: AM | W42: N | Y42: - | AA42: AM | AB42: 1/2VA | AC42: N | AD42: PM | AE42: N | AF42: PM | AG42: N | AH42: Abs | AJ42: AM | AK42: N | AM42: PM | AN42: 4h RTT
...

Sheet Shift3
A1: SHIFT 3 | O1: Date de dernière mise à jour
O2: =Shift1!O2 -> 46295.595
O4: VA | P4: Vacances annuelles | U4: xxx | V4: Congé accordé sous restriction - Rappelable | AB4: CP | AC4: Congé Parental
O5: RTT | P5: Récup. temps de travail | U5: R | V5: Remplacement | AB5: CSS | AC5: Congé sans solde
O6: RHS | P6: Récup. heures supplémentaires | U6: Abs, | V6: Absence - Maladie | AB6: R-CM | AC6: Remplacement Contremaître
O7: RJF | P7: Récup. Jour férié | U7: DS | V7: Délégation syndicale
C9: Adjoints Contremaître | O9: Polyvalent | Q9: Fermentation | S9: Distillation | U9: Renfort arrière | Y9: Meunerie | AA9: Gluten | AC9: Polyvalent | AE9: Polyvalent | AG9: Chaudières
C10: VGG | G10: JBI | I10: YBT | K10: ATR | M10: FPA | O10: FLN | Q10: CKS | S10: PDR | U10: ALZ | Y10: DKS | AA10: IME | AC10: SPT | AE10: MMS | AG10: ADK | AI10: LAX | AK10: JBA
B11: 1 | C11: - | G11: - | I11: AM | J11: Abs | K11: PM | L11: 8h -FT | M11: H. flott. | N11: 8h -FT | O11: - | Q11: - | R11: Abs | S11: - | U11: - | Y11: - | AA11: - | AC11: - | AG11: - | AI11: - | AK11: -
B12: 2 | C12: H. flott | D12: RTT | G12: AM | H12: RHS | I12: PM | J12: Abs | K12: N | L12: R-CM | M12: H. flott. | N12: 4h RTT- | O12: AM | Q12: AM | R12: Abs | S12: AM | T12: RTT- | U12: AM | V12: VA | Y12: AM | AA12: AM | AB12: RTT- | AC12: AM | AG12: AM | AI12: AM | AK12: AM
A13: J | B13: 3 | C13: - | G13: AM | I13: PM | J13: Abs | K13: N | L13: R-CM | M13: - | N13: 4h RTT | O13: AM | Q13: AM | S13: AM | T13: RTT- | U13: AM | Y13: AM | AA13: AM | AB13: RTT- | AC13: AM | AG13: AM | AI13: AM | AK13: AM
A14: A | B14: 4 | C14: - | G14: AM | H14: poly. Arr. | I14: PM | J14: Abs | K14: N | L14: R-CM | M14: - | O14: AM | P14: 8h -FT | Q14: AM | S14: AM | T14: 8h -FT | U14: AM | Y14: AM | AA14: AM | AB14: RTT- | AC14: AM | AG14: AM | AH14: 4h -FT | AI14: AM | AK14: AM
A15: N | B15: 5 | C15: H. flott. | G15: PM | H15: RTT - | I15: N | J15: Abs | K15: - | M15: AM | N15: R-CM | O15: PM | Q15: PM | R15: VA | S15: PM | T15: RTT- | U15: PM | Y15: PM | AA15: PM | AB15: N | AC15: PM | AE15: D | AG15: PM | AI15: PM | AJ15: 4h rhs | AK15: PM
A16: V | B16: 6 | C16: H. flott. | D16: 1h RHS | G16: PM | H16: poly. Arr. | I16: N | J16: Abs | K16: - | M16: AM | N16: R-CM | O16: PM | P16: N | Q16: PM | R16: N | S16: PM | T16: RTT- | U16: PM | V16: R | Y16: PM | AA16: PM | AB16: N | AC16: PM | AE16: D | AG16: PM | AH16: AM | AI16: PM | AK16: PM
A17: I | B17: 7 | C17: H. flott. | D17: R-CM | G17: N | H17: R-CM | I17: - | J17: Abs | K17: R-CM | L17: 2h RTT- | M17: PM | N17: R-CM | O17: N | Q17: N | S17: N | T17: RTT- | U17: N | V17: VA | Y17: N | AA17: N | AC17: N | AD17: RJF | AE17: D | AG17: N | AH17: 0,25 rhs | AI17: N | AK17: N
A18: E | B18: 8 | C18: H. flott. | D18: R-CM | G18: N | H18: R-CM | I18: - | J18: Abs | K18: AM | L18: VA | M18: PM | N18: R-CM | O18: N | Q18: N | R18: VA | S18: N | T18: RTT- | U18: N | V18: R | Y18: N | AA18: N | AC18: N | AE18: D | AG18: N | AI18: N | AK18: N
A19: R | B19: 9 | C19: H. flott. | D19: RJF | G19: - | I19: AM | J19: Abs | K19: PM | L19: R-CM | M19: N | N19: R-CM | O19: - | Q19: - | S19: - | U19: - | Y19: - | AA19: - | AC19: - | AE19: D | AG19: - | AI19: - | AK19: -
B20: 10 | C20: - | G20: - | H20: 4h +FT | I20: AM | J20: Abs | K20: PM | L20: R-CM | M20: N | N20: R-CM | O20: - | Q20: - | S20: - | U20: - | Y20: - | AA20: - | AC20: - | AE20: - | AG20: - | AI20: - | AK20: -
B21: 11 | C21: - | G21: - | I21: AM | J21: Abs | K21: PM | L21: R-CM | M21: N | N21: R-CM | O21: - | Q21: - | S21: - | U21: - | Y21: - | AA21: - | AC21: - | AE21: - | AG21: - | AI21: - | AK21: -
B22: 12 | C22: AM | D22: poly-arr | G22: AM | H22: R-CM | I22: PM | J22: Abs | K22: N | M22: - | O22: D | P22: TP | Q22: 7h-15h | R22: - | S22: - | U22: - | Y22: D | Z22: VA | AA22: 6h-14h | AB22: CP | AC22: D | AD22: TP | AE22: D | AG22: 7h-15h | AI22: - | AK22: -
B23: 13 | C23: AM | D23: Abs | G23: 7h-15h | H23: 1h rhs | I23: PM | J23: Abs | K23: N | L23: R-CM | M23: - | N23: 2h +FT | O23: D | P23: TP | Q23: 7h-15h | R23: 1/2VA | S23: - | U23: - | Y23: D | Z23: VA | AA23: 6h-14h | AB23: CP | AC23: D | AD23: TP | AE23: D | AG23: 7h-15h | AH23: AM | AI23: - | AK23: -
A24: 2 | B24: 14 | C24: PM | D24: Abs | G24: 14h-01h | H24: R-CM | I24: PM | J24: Abs | K24: - | M24: AM | N24: R-CM | O24: D | P24: TP | Q24: 7h-15h | R24: 1/2VA | S24: D | T24: CT | U24: D | V24: CP | Y24: D | Z24: VA | AA24: 6h-14h | AB24: RHS | AC24: D | AD24: TP | AE24: D | AG24: AM | AH24: 2h +FT | AI24: D | AJ24: TP | AK24: D | AL24: PM
A25: 0 | B25: 15 | C25: PM | D25: Abs | G25: PM | H25: R-CM | I25: N | J25: Abs | K25: - | M25: AM | N25: R-CM | O25: - | Q25: F | R25: 2h RTT | S25: D | T25: CT | U25: D | V25: CP | Y25: - | AA25: - | AC25: - | AE25: D | AG25: - | AI25: D | AJ25: TP | AK25: D-F | AL25: 4h rhs
A26: 2 | B26: 16 | C26: N | D26: Abs | G26: - | H26: 3h +FT | I26: - | J26: Abs | K26: AM | L26: R-CM | M26: PM | N26: R-CM | O26: - | Q26: - | R26: 2h RTT | S26: D | T26: CT | U26: D | V26: VA | Y26: - | AA26: - | AC26: - | AE26: D | AG26: - | AI26: D | AJ26: TP | AK26: D | AL26: RHS
A27: 6 | B27: 17 | C27: N | D27: Abs | G27: - | H27: 18h-22h | I27: - | J27: Abs | K27: AM | L27: R-CM | M27: PM | N27: 8h -FT | O27: - | Q27: - | S27: - | U27: - | Y27: - | AA27: - | AC27: - | AE27: - | AG27: - | AI27: - | AK27: -
B28: 18 | C28: N | D28: Abs | G28: - | I28: - | J28: Abs | K28: AM | L28: R-CM | M28: PM | N28: Abs | O28: - | Q28: - | S28: - | U28: - | Y28: - | AA28: - | AC28: - | AE28: - | AG28: - | AI28: - | AK28: -
B29: 19 | C29: - | G29: AM | H29: R-CM | I29: D | J29: Abs | K29: PM | M29: N | N29: Abs | O29: AM | Q29: AM | S29: AM | U29: AM | Y29: AM | AA29: AM | AB29: N | AC29: AM | AD29: 2h RTT | AE29: D | AG29: AM | AI29: AM | AK29: AM | AL29: 1h rhs
B30: 20 | C30: - | G30: AM | H30: R-CM | I30: D | J30: Abs | K30: PM | L30: meunerie | M30: N | N30: Abs | O30: AM | Q30: AM | S30: AM | T30: 4h rhs | U30: AM | Y30: AM | Z30: D-F | AA30: AM | AB30: N | AC30: AM | AE30: D | AG30: AM | AI30: AM | AK30: AM
B31: 21 | C31: AM | D31: R-CM | G31: 7h-15h | H31: F | I31: D | J31: Abs | K31: N | L31: DS-CE | M31: N | N31: Abs | O31: PM | P31: F | Q31: PM | R31: 1/2VA | S31: PM | U31: PM | V31: Abs | Y31: PM | AA31: PM | AB31: N | AC31: PM | AE31: D | AG31: PM | AI31: PM | AJ31: F | AK31: PM
B32: 22 | C32: PM | D32: R-CM | G32: 7h-15h | H32: 3h rhs | I32: - | J32: Abs | K32: AM | L32: R-CM | M32: - | N32: Abs | O32: PM | P32: R | Q32: PM | R32: N | S32: PM | U32: PM | V32: 3h RTT | Y32: PM | Z32: Abs | AA32: PM | AB32: N | AC32: PM | AE32: D | AG32: PM | AH32: 2h rhs | AI32: PM | AJ32: Abs | AK32: PM
B33: 23 | C33: PM | D33: VA | G33: 7h-15h | H33: F | I33: - | J33: Abs | K33: - | M33: AM | N33: Abs | O33: PM | P33: gluten | Q33: N | S33: N | U33: N | Y33: N | Z33: RJF | AA33: N | AC33: N | AE33: D | AG33: N | AI33: N | AJ33: Abs | AK33: N
B34: 24 | C34: PM | D34: VA | G34: - | I34: - | J34: Abs | K34: - | L34: 2h RTT | M34: AM | N34: Abs | O34: PM | P34: gluten | Q34: N | S34: N | U34: N | Y34: N | AA34: N | AC34: N | AE34: - | AG34: N | AI34: N | AJ34: Abs | AK34: N
B35: 25 | C35: PM | D35: VA | G35: - | I35: - | J35: Abs | K35: - | M35: PM | N35: Abs | O35: N | P35: PM | Q35: N | S35: N | U35: N | Y35: N | AA35: N | AC35: N | AE35: - | AG35: N | AI35: N | AJ35: Abs | AK35: N | AL35: -
B36: 26 | C36: N | D36: R-CM | G36: AM | H36: poly. Arr. | I36: D | J36: Abs | K36: 7h-15h | L36: F | M36: PM | N36: Abs | O36: - | Q36: - | S36: - | U36: - | Y36: - | AA36: - | AC36: - | AE36: - | AG36: - | AI36: - | AK36: - | AL36: F
B37: 27 | C37: N | D37: 4h RTT | G37: AM | H37: RHS | I37: D | J37: Abs | K37: 7h-15h | L37: F | M37: PM | N37: Abs | O37: - | Q37: - | S37: - | U37: - | Y37: - | AA37: - | AC37: - | AE37: - | AF37: AM | AG37: - | AI37: - | AK37: - | AL37: F
B38: 28 | C38: - | G38: PM | H38: RHS | I38: D | J38: Abs | K38: 7h-15h | L38: R | M38: N | N38: Abs | O38: AM | Q38: AM | S38: AM | T38: CT | U38: AM | V38: PM | Y38: AM | AA38: AM | AB38: N | AC38: AM | AE38: AM | AG38: AM | AH38: D-CPPT | AI38: AM | AK38: AM | AL38: F
B39: 29 | C39: - | G39: PM | H39: VA | I39: D | J39: Abs | K39: - | M39: N | N39: Abs | O39: AM | Q39: AM | S39: AM | T39: CT | U39: AM | V39: PM | Y39: AM | AA39: AM | AB39: N | AC39: AM | AD39: 1/2RJF | AE39: AM | AG39: AM | AI39: AM | AK39: - | AL39: AM
B40: 30 | C40: AM | D40: Abs | G40: 18h-06h | H40: R-CM | I40: D | J40: Abs | K40: - | M40: - | N40: Abs | O40: PM | Q40: PM | S40: PM | U40: PM | V40: N | Y40: PM | AA40: PM | AB40: N | AC40: N | AD40: Abs | AE40: PM | AG40: PM | AI40: PM | AK40: PM
B41: 31 | C41: R-CM | D41: 06h-16h | G41: N | H41: 19h-22h | I41: - | J41: Abs | K41: - | M41: - | N41: Abs | O41: PM | Q41: PM | R41: RJF | S41: PM | U41: PM | V41: R | Y41: PM | AA41: PM | AB41: N | AC41: PM | AD41: N | AE41: PM | AG41: PM | AI41: PM | AK41: PM | AL41: VA
B42: 1 | C42: AM | D42: R-CM | G42: N | H42: poly-arr | I42: - | J42: Abs | K42: - | M42: - | N42: Abs | O42: PM | Q42: PM | S42: PM | U42: PM | Y42: PM | AA42: PM | AB42: N | AC42: PM | AD42: N | AE42: PM | AG42: PM | AI42: PM | AK42: PM
...

Sheet Shift4
A1: SHIFT 4 | O1: Date de dernière mise à jour
O2: =Shift1!O2 -> 46295.595
O4: VA | P4: Vacances annuelles | U4: xxx | V4: Congé accordé sous restriction - Rappelable | AB4: CP | AC4: Congé Parental
O5: RTT | P5: Récup. temps de travail | U5: R | V5: Remplacement | AB5: CSS | AC5: Congé sans solde
O6: RHS | P6: Récup. heures supplémentaires | U6: Abs, | V6: Absence - Maladie | AB6: R-CM | AC6: Remplacement Contremaître
O7: RJF | P7: Récup. Jour férié | U7: DS | V7: Délégation syndicale
C9: Adjoints Contremaître | O9: Polyvalent | Q9: Fermentation | S9: Distillation | U9: Renfort arrière | W9: Renfort avant | Y9: Meunerie | AA9: Gluten | AC9: Polyvalent | AE9: Polyvalent | AG9: Chaudières
C10: VGG | G10: JBI | I10: YBT | K10: ATR | M10: FPA | O10: FPS | S10: PAM | U10: QBY | W10: SMK | Y10: CGI | AA10: RDT | AC10: GPO | AE10: GSK | AG10: GBT | AI10: MHI | AK10: JBS
B11: 1 | C11: - | G11: - | I11: AM | J11: Abs | K11: PM | L11: 8h -FT | M11: H. flott. | N11: 8h -FT | O11: PM | Q11: PM | S11: PM | U11: PM | W11: N | Y11: PM | Z11: AM | AA11: N | AB11: PM | AC11: PM | AE11: PM | AF11: Abs | AG11: PM | AI11: PM | AK11: PM
B12: 2 | C12: H. flott | D12: RTT | G12: AM | H12: RHS | I12: PM | J12: Abs | K12: N | L12: R-CM | M12: H. flott. | N12: 4h RTT- | O12: N | Q12: N | S12: N | U12: N | V12: 10h-18h | W12: - | Y12: N | AA12: - | AB12: N | AC12: N | AD12: VA | AE12: N | AF12: Abs | AG12: N | AI12: N | AJ12: VA | AK12: N
A13: J | B13: 3 | C13: - | G13: AM | I13: PM | J13: Abs | K13: N | L13: R-CM | M13: - | N13: 4h RTT | O13: N | Q13: N | S13: N | U13: N | W13: - | Y13: N | AA13: - | AB13: N | AC13: N | AD13: Abs | AE13: N | AF13: Abs | AG13: N | AI13: N | AK13: N
A14: A | B14: 4 | C14: - | G14: AM | H14: poly. Arr. | I14: PM | J14: Abs | K14: N | L14: R-CM | M14: - | O14: N | Q14: N | S14: N | U14: N | W14: - | Y14: N | AA14: - | AB14: N | AC14: N | AE14: N | AF14: Abs | AG14: N | AI14: N | AK14: N
A15: N | B15: 5 | C15: H. flott. | G15: PM | H15: RTT - | I15: N | J15: Abs | K15: - | M15: AM | N15: R-CM | O15: - | Q15: 7h-15h | S15: - | U15: 10h-18h | W15: D | X15: RTT- | Y15: - | AA15: - | AB15: - | AC15: - | AE15: - | AF15: Abs | AG15: - | AI15: - | AK15: -
A16: V | B16: 6 | C16: H. flott. | D16: 1h RHS | G16: PM | H16: poly. Arr. | I16: N | J16: Abs | K16: - | M16: AM | N16: R-CM | O16: - | Q16: 7h-15h | S16: - | U16: 10h-18h | W16: D | X16: RTT- | Y16: - | AA16: - | AB16: - | AC16: - | AE16: - | AF16: Abs | AG16: - | AI16: - | AK16: -
A17: I | B17: 7 | C17: H. flott. | D17: R-CM | G17: N | H17: R-CM | I17: - | J17: Abs | K17: R-CM | L17: 2h RTT- | M17: PM | N17: R-CM | O17: AM | Q17: AM | S17: AM | T17: VA | U17: AM | V17: distillation | W17: D | X17: 5h RTT | Y17: AM | AA17: D | AB17: AM | AC17: AM | AE17: AM | AF17: Abs | AG17: AM | AH17: 3h RTT | AI17: AM | AJ17: VA | AK17: AM
A18: E | B18: 8 | C18: H. flott. | D18: R-CM | G18: N | H18: R-CM | I18: - | J18: Abs | K18: AM | L18: VA | M18: PM | N18: R-CM | O18: AM | Q18: AM | S18: AM | T18: gluten | U18: AM | V18: distillation | W18: - | X18: 3h RTT- | Y18: AM | AA18: D | AB18: AM | AC18: AM | AE18: AM | AF18: Abs | AG18: AM | AH18: 5h RTT | AI18: AM | AK18: AM
A19: R | B19: 9 | C19: H. flott. | D19: RJF | G19: - | I19: AM | J19: Abs | K19: PM | L19: R-CM | M19: N | N19: R-CM | O19: PM | Q19: PM | S19: PM | T19: gluten | U19: PM | V19: distillation | W19: - | Y19: PM | Z19: AM | AA19: D | AB19: PM | AC19: PM | AD19: RTT- | AE19: PM | AF19: Abs | AG19: PM | AI19: PM | AK19: PM
B20: 10 | C20: - | G20: - | H20: 4h +FT | I20: AM | J20: Abs | K20: PM | L20: R-CM | M20: N | N20: R-CM | O20: PM | Q20: PM | S20: PM | T20: gluten | U20: PM | V20: N | W20: - | Y20: PM | Z20: AM | AA20: - | AC20: PM | AD20: distillation | AE20: PM | AF20: Abs | AG20: PM | AI20: PM | AK20: PM
B21: 11 | C21: - | G21: - | I21: AM | J21: Abs | K21: PM | L21: R-CM | M21: N | N21: R-CM | O21: PM | Q21: PM | S21: PM | T21: AM | U21: PM | V21: gluten | W21: - | Y21: AM | Z21: 0,25 rhs | AA21: - | AC21: PM | AE21: PM | AF21: Abs | AG21: PM | AI21: PM | AK21: PM
B22: 12 | C22: AM | D22: poly-arr | G22: AM | H22: R-CM | I22: PM | J22: Abs | K22: N | M22: - | O22: N | Q22: N | S22: N | T22: gluten | U22: N | V22: distillation | W22: N | Y22: N | AA22: AM | AC22: 20h-06h | AD22: 2h +FT | AE22: N | AF22: Abs | AG22: N | AI22: N | AK22: N
B23: 13 | C23: AM | D23: Abs | G23: 7h-15h | H23: 1h rhs | I23: PM | J23: Abs | K23: N | L23: R-CM | M23: - | N23: 2h +FT | O23: N | P23: - | Q23: N | S23: N | T23: gluten | U23: N | V23: distillation | W23: N | Y23: N | AA23: AM | AC23: N | AD23: poly. Arr. | AE23: N | AF23: Abs | AG23: N | AI23: N | AK23: N | AL23: VA
A24: 2 | B24: 14 | C24: PM | D24: Abs | G24: 14h-01h | H24: R-CM | I24: PM | J24: Abs | K24: - | M24: AM | N24: R-CM | O24: - | P24: D-F | Q24: - | S24: N | T24: terr. Arr. | U24: - | W24: - | Y24: - | AA24: PM | AB24: N | AC24: - | AE24: - | AF24: Abs | AG24: - | AI24: - | AK24: -
A25: 0 | B25: 15 | C25: PM | D25: Abs | G25: PM | H25: R-CM | I25: N | J25: Abs | K25: - | M25: AM | N25: R-CM | O25: - | Q25: - | S25: - | U25: - | W25: - | Y25: - | AA25: PM | AC25: - | AE25: - | AF25: Abs | AG25: - | AI25: - | AK25: -
A26: 2 | B26: 16 | C26: N | D26: Abs | G26: - | H26: 3h +FT | I26: - | J26: Abs | K26: AM | L26: R-CM | M26: PM | N26: R-CM | O26: AM | Q26: AM | S26: AM | U26: AM | V26: gluten | W26: AM | Y26: AM | Z26: RHS | AA26: N | AC26: AM | AE26: AM | AF26: Abs | AG26: AM | AH26: VA | AI26: AM | AK26: AM
A27: 6 | B27: 17 | C27: N | D27: Abs | G27: - | H27: 18h-22h | I27: - | J27: Abs | K27: AM | L27: R-CM | M27: PM | N27: 8h -FT | O27: AM | Q27: AM | S27: AM | T27: 06h-18h | U27: AM | V27: gluten | W27: AM | Y27: AM | AA27: N | AC27: AM | AE27: AM | AF27: Abs | AG27: AM | AI27: AM | AK27: AM
B28: 18 | C28: N | D28: Abs | G28: - | I28: - | J28: Abs | K28: AM | L28: R-CM | M28: PM | N28: Abs | O28: AM | Q28: AM | S28: AM | U28: AM | V28: gluten | W28: AM | Y28: AM | Z28: 2h rhs | AA28: N | AB28: - | AC28: AM | AE28: AM | AF28: Abs | AG28: AM | AI28: AM | AK28: AM
B29: 19 | C29: - | G29: AM | H29: R-CM | I29: D | J29: Abs | K29: PM | M29: N | N29: Abs | O29: PM | Q29: PM | S29: PM | T29: meunerie | U29: PM | V29: distillation | W29: PM | Y29: PM | Z29: CT | AA29: - | AB29: D-F | AC29: PM | AE29: PM | AF29: Abs | AG29: PM | AH29: 2h RTT | AI29: PM | AK29: PM
B30: 20 | C30: - | G30: AM | H30: R-CM | I30: D | J30: Abs | K30: PM | L30: meunerie | M30: N | N30: Abs | O30: PM | Q30: PM | S30: N | T30: terr. Arr. | U30: PM | V30: distillation | W30: PM | X30: AM | Y30: PM | Z30: CT | AA30: - | AB30: D-F | AC30: PM | AE30: PM | AF30: Abs | AG30: PM | AI30: PM | AK30: PM
B31: 21 | C31: AM | D31: R-CM | G31: 7h-15h | H31: F | I31: D | J31: Abs | K31: N | L31: DS-CE | M31: N | N31: Abs | O31: N | Q31: N | S31: N | U31: PM DS-CE | V31: 4h +FT | W31: N | Y31: N | AA31: AM | AB31: D-F | AC31: N | AE31: N | AF31: CP | AG31: N | AH31: 2h RTT | AI31: N | AK31: N
B32: 22 | C32: PM | D32: R-CM | G32: 7h-15h | H32: 3h rhs | I32: - | J32: Abs | K32: AM | L32: R-CM | M32: - | N32: Abs | O32: N | Q32: N | S32: N | U32: N | V32: 14h-00h | W32: N | Y32: N | Z32: 2h RTT | AA32: AM | AB32: D-F | AC32: N | AD32: R | AE32: N | AF32: CP | AG32: N | AH32: 2h +FT | AI32: N | AK32: N | AL32: VA
B33: 23 | C33: PM | D33: VA | G33: 7h-15h | H33: F | I33: - | J33: Abs | K33: - | M33: AM | N33: Abs | O33: - | Q33: - | S33: - | U33: - | W33: - | Y33: - | AA33: PM | AB33: D-F | AC33: - | AE33: - | AF33: Abs | AG33: - | AI33: - | AK33: -
B34: 24 | C34: PM | D34: VA | G34: - | I34: - | J34: Abs | K34: - | L34: 2h RTT | M34: AM | N34: Abs | O34: - | Q34: - | S34: - | U34: - | W34: - | Y34: - | AA34: PM | AB34: - | AC34: - | AE34: - | AF34: Abs | AG34: - | AI34: - | AK34: -
B35: 25 | C35: PM | D35: VA | G35: - | I35: - | J35: Abs | K35: - | M35: PM | N35: Abs | O35: - | Q35: - | S35: - | U35: - | W35: - | Y35: - | AC35: - | AE35: - | AF35: Abs | AG35: - | AI35: - | AK35: -
B36: 26 | C36: N | D36: R-CM | G36: AM | H36: poly. Arr. | I36: D | J36: Abs | K36: 7h-15h | L36: F | M36: PM | N36: Abs | O36: - | Q36: 6h-14h | S36: AM | T36: ferm. Liqu. | U36: 6h-14h | W36: D | Y36: D | Z36: CT | AA36: - | AC36: D | AD36: 2h RTT | AE36: D | AF36: CP | AG36: - | AI36: 7h-15h | AJ36: RJF | AK36: - | AL36: F
B37: 27 | C37: N | D37: 4h RTT | G37: AM | H37: RHS | I37: D | J37: Abs | K37: 7h-15h | L37: F | M37: PM | N37: Abs | O37: - | Q37: 6h-14h | S37: AM | T37: ferm. Liqu. | U37: 6h-14h | W37: D | Y37: D | Z37: CT | AA37: - | AC37: D | AD37: 2h RTT | AE37: D | AF37: CP | AG37: - | AI37: 7h-15h | AJ37: RJF | AK37: - | AL37: F
B38: 28 | C38: - | G38: PM | H38: RHS | I38: D | J38: Abs | K38: 7h-15h | L38: R | M38: N | N38: Abs | O38: D | P38: VA | Q38: 6h-14h | S38: D | T38: VA | U38: 6h-14h | W38: D | Y38: D | Z38: CT | AA38: 6h-14h | AC38: D | AD38: - | AE38: D | AF38: CP | AG38: 7h-15h | AH38: RJF | AI38: 7h-15h | AJ38: VA | AK38: D | AL38: F
B39: 29 | C39: - | G39: PM | H39: VA | I39: D | J39: Abs | K39: - | M39: N | N39: Abs | O39: D | P39: VA | Q39: - | S39: - | T39: 8h +FT | U39: - | W39: - | Y39: - | AA39: 6h-14h | AB39: RHS | AC39: - | AD39: AM | AE39: - | AF39: Abs | AG39: 7h-15h | AH39: RJF | AI39: - | AK39: D | AL39: -
B40: 30 | C40: AM | D40: Abs | G40: 18h-06h | H40: R-CM | I40: D | J40: Abs | K40: - | M40: - | N40: Abs | O40: D | P40: RTT | Q40: - | S40: - | U40: - | W40: - | Y40: - | AA40: 6h-14h | AB40: RJF | AC40: - | AE40: - | AF40: Abs | AG40: 7h-15h | AH40: VA | AI40: - | AK40: D | AL40: -
B41: 31 | C41: R-CM | D41: 06h-16h | G41: N | H41: 19h-22h | I41: - | J41: Abs | K41: - | M41: - | N41: Abs | O41: - | Q41: - | S41: - | T41: AM | U41: - | W41: - | Y41: - | AA41: - | AC41: - | AE41: - | AF41: Abs | AG41: - | AI41: - | AK41: -
B42: 1 | C42: AM | D42: R-CM | G42: N | H42: poly-arr | I42: - | J42: Abs | K42: - | M42: - | N42: Abs | O42: - | Q42: - | S42: - | U42: - | W42: - | Y42: - | AA42: - | AC42: - | AE42: - | AF42: Abs | AG42: - | AI42: - | AK42: -
...

Sheet Shift5
A1: SHIFT 5 | O1: Date de dernière mise à jour
O2: =Shift1!O2 -> 46295.595
O4: VA | P4: Vacances annuelles | U4: xxx | V4: Congé accordé sous restriction - Rappelable | AB4: CP | AC4: Congé Parental
O5: RTT | P5: Récup. temps de travail | U5: R | V5: Remplacement | AB5: CSS | AC5: Congé sans solde
O6: RHS | P6: Récup. heures supplémentaires | U6: Abs, | V6: Absence - Maladie | AB6: R-CM | AC6: Remplacement Contremaître
O7: RJF | P7: Récup. Jour férié | U7: DS | V7: Délégation syndicale
C9: Adjoints Contremaître | O9: Polyvalent | Q9: Fermentation | S9: Distillation | U9: Renfort arrière | W9: Renfort arrière | Y9: Meunerie | AA9: Gluten | AC9: Polyvalent | AE9: Polyvalent | AG9: Chaudières
C10: VGG | G10: JBI | I10: YBT | K10: ATR | M10: FPA | Q10: CHD | S10: SMA | U10: AAI | W10: LHS | Y10: CDE | AA10: SLT | AC10: GBT | AE10: PLZ | AG10: RCO | AI10: SPS | AK10: LDY
B11: 1 | C11: - | G11: - | I11: AM | J11: Abs | K11: PM | L11: 8h -FT | M11: H. flott. | N11: 8h -FT | Q11: PM | S11: 6h-14h | T11: TP | U11: 6h-14h | V11: 8h -FT | W11: N | X11: VA | Y11: AM | Z11: PM | AA11: - | AC11: D | AD11: CP | AE11: 7h-15h | AF11: - | AG11: D | AH11: CP | AI11: 7h-15h | AJ11: RJF | AK11: AM | AL11: 8h -FT
B12: 2 | C12: H. flott | D12: RTT | G12: AM | H12: RHS | I12: PM | J12: Abs | K12: N | L12: R-CM | M12: H. flott. | N12: 4h RTT- | Q12: N | S12: 6h-14h | T12: RTT | U12: 6h-14h | V12: RTT | W12: - | Y12: PM | AA12: - | AC12: D | AD12: VA | AE12: 7h-15h | AF12: - | AG12: D | AH12: RTT- | AI12: 7h-15h | AJ12: VA | AK12: D | AL12: RTT-
A13: J | B13: 3 | C13: - | G13: AM | I13: PM | J13: Abs | K13: N | L13: R-CM | M13: - | N13: 4h RTT | Q13: N | S13: - | U13: - | W13: - | Y13: PM | AA13: - | AC13: - | AE13: - | AG13: - | AI13: - | AK13: -
A14: A | B14: 4 | C14: - | G14: AM | H14: poly. Arr. | I14: PM | J14: Abs | K14: N | L14: R-CM | M14: - | Q14: N | S14: - | U14: - | W14: - | Y14: PM | AA14: - | AC14: - | AE14: - | AG14: - | AI14: - | AK14: -
A15: N | B15: 5 | C15: H. flott. | G15: PM | H15: RTT - | I15: N | J15: Abs | K15: - | M15: AM | N15: R-CM | Q15: 7h-15h | S15: AM | T15: VA | U15: AM | W15: 6h-14h | X15: RJF | Y15: N | Z15: RTT- | AA15: AM | AC15: AM | AD15: 2h RTT- | AE15: AM | AG15: AM | AH15: RTT- | AI15: AM | AK15: AM
A16: V | B16: 6 | C16: H. flott. | D16: 1h RHS | G16: PM | H16: poly. Arr. | I16: N | J16: Abs | K16: - | M16: AM | N16: R-CM | Q16: 7h-15h | S16: AM | T16: VA | U16: AM | W16: 6h-14h | X16: VA | Y16: N | Z16: 4h RTT- | AA16: AM | AC16: AM | AE16: AM | AF16: Abs | AG16: AM | AH16: RTT- | AI16: AM | AK16: AM | AL16: PM
A17: I | B17: 7 | C17: H. flott. | D17: R-CM | G17: N | H17: R-CM | I17: - | J17: Abs | K17: R-CM | L17: 2h RTT- | M17: PM | N17: R-CM | Q17: AM | S17: AM | T17: 1/2VA | U17: PM | W17: 6h-14h | X17: VA | Y17: - | Z17: 4h RTT | AA17: PM | AC17: PM | AE17: PM | AF17: Abs | AG17: PM | AH17: RTT- | AI17: distill. | AJ17: 1/2VA | AK17: PM
A18: E | B18: 8 | C18: H. flott. | D18: R-CM | G18: N | H18: R-CM | I18: - | J18: Abs | K18: AM | L18: VA | M18: PM | N18: R-CM | Q18: AM | S18: PM | T18: 1/2VA | U18: PM | V18: R | W18: - | Y18: - | AA18: PM | AC18: PM | AE18: PM | AF18: Abs | AG18: PM | AH18: RTT- | AI18: PM | AK18: PM | AL18: meunerie
A19: R | B19: 9 | C19: H. flott. | D19: RJF | G19: - | I19: AM | J19: Abs | K19: PM | L19: R-CM | M19: N | N19: R-CM | Q19: PM | S19: N | T19: terr. Arr. | U19: N | W19: - | Y19: AM | AA19: N | AC19: N | AE19: N | AF19: Abs | AG19: N | AI19: N | AJ19: distill. | AK19: N | AL19: meunerie
B20: 10 | C20: - | G20: - | H20: 4h +FT | I20: AM | J20: Abs | K20: PM | L20: R-CM | M20: N | N20: R-CM | Q20: PM | R20: VA | S20: N | U20: N | W20: - | Y20: AM | Z20: R | AA20: N | AC20: N | AD20: VA | AE20: N | AF20: Abs | AG20: N | AI20: N | AK20: N | AL20: meunerie
B21: 11 | C21: - | G21: - | I21: AM | J21: Abs | K21: PM | L21: R-CM | M21: N | N21: R-CM | Q21: PM | S21: N | T21: Abs | U21: N | W21: - | Y21: AM | AA21: N | AC21: N | AE21: N | AF21: Abs | AG21: N | AI21: N | AJ21: distill. | AK21: N | AL21: meunerie
B22: 12 | C22: AM | D22: poly-arr | G22: AM | H22: R-CM | I22: PM | J22: Abs | K22: N | M22: - | Q22: N | R22: D | S22: - | T22: Abs | U22: - | W22: AM | X22: 7h RTT | Y22: PM | Z22: 2h RTT | AA22: - | AB22: N | AC22: - | AD22: N | AE22: - | AG22: - | AI22: - | AK22: -
B23: 13 | C23: AM | D23: Abs | G23: 7h-15h | H23: 1h rhs | I23: PM | J23: Abs | K23: N | L23: R-CM | M23: - | N23: 2h +FT | Q23: N | S23: - | T23: Abs | U23: - | W23: AM | Y23: PM | Z23: poly. Arr. | AA23: - | AC23: - | AE23: - | AG23: - | AI23: - | AK23: -
A24: 2 | B24: 14 | C24: PM | D24: Abs | G24: 14h-01h | H24: R-CM | I24: PM | J24: Abs | K24: - | M24: AM | N24: R-CM | Q24: - | S24: AM | T24: Abs | U24: AM | W24: PM | X24: 2h RTT | Y24: PM | Z24: F | AA24: AM | AC24: AM | AE24: F | AF24: 2h +FT | AG24: F | AH24: 2h +FT | AI24: AM | AJ24: distill. | AK24: AM | AL24: meunerie
A25: 0 | B25: 15 | C25: PM | D25: Abs | G25: PM | H25: R-CM | I25: N | J25: Abs | K25: - | M25: AM | N25: R-CM | Q25: - | S25: PM | T25: Abs | U25: AM | W25: PM | X25: D-F | Y25: 18h-06h | Z25: 4h +FT | AA25: AM | AC25: AM | AE25: 6h-18h | AF25: 4h +FT | AG25: AM | AI25: AM | AK25: AM | AL25: meunerie
A26: 2 | B26: 16 | C26: N | D26: Abs | G26: - | H26: 3h +FT | I26: - | J26: Abs | K26: AM | L26: R-CM | M26: PM | N26: R-CM | Q26: AM | S26: PM | T26: Abs | U26: PM | W26: N | Y26: - | AA26: PM | AC26: PM | AE26: PM | AG26: PM | AI26: PM | AK26: 6h-18h | AL26: meunerie
A27: 6 | B27: 17 | C27: N | D27: Abs | G27: - | H27: 18h-22h | I27: - | J27: Abs | K27: AM | L27: R-CM | M27: PM | N27: 8h -FT | Q27: AM | S27: PM | T27: Abs | U27: PM | W27: N | X27: 1/2VA | Y27: - | AA27: PM | AB27: RHS | AC27: PM | AE27: PM | AG27: PM | AI27: PM | AJ27: distill. | AK27: PM | AL27: meunerie
B28: 18 | C28: N | D28: Abs | G28: - | I28: - | J28: Abs | K28: AM | L28: R-CM | M28: PM | N28: Abs | Q28: AM | S28: PM | T28: Abs | U28: PM | W28: N | X28: VA | Y28: - | AA28: PM | AC28: PM | AE28: PM | AG28: PM | AI28: PM | AJ28: distill. | AK28: PM
B29: 19 | C29: - | G29: AM | H29: R-CM | I29: D | J29: Abs | K29: PM | M29: N | N29: Abs | Q29: PM | S29: N | T29: Abs | U29: N | W29: - | Y29: D | AA29: N | AB29: AM | AC29: N | AE29: N | AF29: Ferm. Liq. | AG29: N | AI29: N | AJ29: distill. | AK29: N | AL29: meunerie
B30: 20 | C30: - | G30: AM | H30: R-CM | I30: D | J30: Abs | K30: PM | L30: meunerie | M30: N | N30: Abs | Q30: PM | R30: D-F | S30: N | T30: Abs | U30: N | V30: distillation | W30: - | Y30: D | Z30: AM | AA30: N | AB30: AM | AC30: N | AE30: N | AF30: Ferm. Liq. | AG30: N | AI30: N | AJ30: VA | AK30: N | AL30: meunerie
B31: 21 | C31: AM | D31: R-CM | G31: 7h-15h | H31: F | I31: D | J31: Abs | K31: N | L31: DS-CE | M31: N | N31: Abs | Q31: N | S31: - | T31: Abs | U31: - | W31: AM | Y31: D | Z31: PM | AA31: - | AC31: - | AE31: - | AG31: - | AI31: PM | AJ31: chaudières | AK31: -
B32: 22 | C32: PM | D32: R-CM | G32: 7h-15h | H32: 3h rhs | I32: - | J32: Abs | K32: AM | L32: R-CM | M32: - | N32: Abs | Q32: N | S32: - | T32: Abs | U32: - | W32: AM | Y32: - | AA32: - | AC32: - | AE32: - | AG32: - | AI32: - | AK32: -
B33: 23 | C33: PM | D33: VA | G33: 7h-15h | H33: F | I33: - | J33: Abs | K33: - | M33: AM | N33: Abs | Q33: - | S33: AM | T33: Abs | U33: AM | W33: PM | X33: R | Y33: - | AA33: AM | AC33: AM | AD33: 4h rhs | AE33: AM | AG33: AM | AI33: AM | AJ33: distill. | AK33: AM | AL33: meunerie
B34: 24 | C34: PM | D34: VA | G34: - | I34: - | J34: Abs | K34: - | L34: 2h RTT | M34: AM | N34: Abs | Q34: - | S34: AM | T34: Abs | U34: AM | W34: PM | Y34: - | AA34: AM | AC34: AM | AD34: 4h rhs | AE34: AM | AG34: AM | AI34: AM | AJ34: 2h RTT | AK34: AM | AL34: meunerie
B35: 25 | C35: PM | D35: VA | G35: - | I35: - | J35: Abs | K35: - | M35: PM | N35: Abs | Q35: - | S35: AM | T35: Abs | U35: AM | W35: PM | X35: VA | Y35: - | AA35: AM | AC35: AM | AD35: 4h rhs | AE35: AM | AG35: 06-18h | AH35: 4h +FT | AI35: AM | AJ35: RJF | AK35: AM | AL35: meunerie
B36: 26 | C36: N | D36: R-CM | G36: AM | H36: poly. Arr. | I36: D | J36: Abs | K36: 7h-15h | L36: F | M36: PM | N36: Abs | Q36: 6h-14h | R36: F | S36: PM | T36: Abs | U36: PM | V36: distillation | W36: N | X36: Abs | Y36: 06h-18h | Z36: 4h +FT | AA36: PM | AB36: AM | AC36: PM | AE36: PM | AF36: meunerie | AG36: PM | AI36: chaudières | AJ36: 1h +FT | AK36: PM | AL36: F
B37: 27 | C37: N | D37: 4h RTT | G37: AM | H37: RHS | I37: D | J37: Abs | K37: 7h-15h | L37: F | M37: PM | N37: Abs | Q37: 6h-14h | R37: F | S37: PM | T37: terr. Arr. | U37: PM | V37: distillation | W37: N | X37: - | Y37: AM | Z37: poly. Arr. | AA37: PM | AB37: AM | AC37: PM | AE37: PM | AF37: meunerie | AG37: PM | AI37: PM | AJ37: chaudières | AK37: PM | AL37: F
B38: 28 | C38: - | G38: PM | H38: RHS | I38: D | J38: Abs | K38: 7h-15h | L38: R | M38: N | N38: Abs | Q38: 6h-14h | R38: F | S38: N | T38: Abs | U38: N | V38: distillation | W38: - | X38: PM | Y38: PM | AA38: N | AB38: AM | AC38: N | AE38: N | AF38: meunerie | AG38: N | AI38: N | AJ38: 14h-23h | AK38: N | AL38: F
B39: 29 | C39: - | G39: PM | H39: VA | I39: D | J39: Abs | K39: - | M39: N | N39: Abs | Q39: - | S39: N | T39: Abs | U39: N | V39: Abs | W39: - | Y39: PM | Z39: chaudière | AA39: N | AB39: AM | AC39: N | AE39: N | AF39: poly. Arr. | AG39: N | AI39: N | AK39: N | AL39: N
B40: 30 | C40: AM | D40: Abs | G40: 18h-06h | H40: R-CM | I40: D | J40: Abs | K40: - | M40: - | N40: Abs | Q40: - | S40: - | U40: - | W40: AM | Y40: N | Z40: 4h RTT | AA40: - | AC40: - | AE40: - | AG40: - | AI40: - | AK40: -
B41: 31 | C41: R-CM | D41: 06h-16h | G41: N | H41: 19h-22h | I41: - | J41: Abs | K41: - | M41: - | N41: Abs | Q41: - | S41: - | U41: - | W41: AM | X41: R | Y41: N | Z41: 8h -FT | AA41: - | AC41: - | AE41: - | AG41: - | AI41: - | AK41: -
B42: 1 | C42: AM | D42: R-CM | G42: N | H42: poly-arr | I42: - | J42: Abs | K42: - | M42: - | N42: Abs | Q42: - | S42: - | U42: - | W42: AM | X42: R | Y42: N | Z42: 8h -FT | AA42: - | AC42: - | AE42: - | AG42: - | AI42: - | AK42: -
...

Sheet Opérateurs
A1: Opérateurs en formation - 2026 | F1: Date de dernière mise à jour
F2: =Shift1!O2 -> 46295.595
C4: VA | D4: Vacances annuelles | I4: xxx | J4: Congé accordé sous restriction - Rappelable | P4: CP | Q4: Congé Parental
C5: RTT | D5: Récup. temps de travail | I5: R | J5: Remplacement | P5: CSS | Q5: Congé sans solde
C6: RHS | D6: Récup. heures supplémentaires | I6: Abs. | J6: Absence - Maladie
C7: RJF | D7: Récup. Jour férié | I7: DS | J7: Délégation syndicale
C9: Meunerie | E9: Distillation | G9: chaudières éq. 1 | I9: chaudières éq. 5 | K9: chaudières éq. 3 | M9: Gluten | Q9: Distillation éq. 1 | S9: Distillation éq. 5
C10: SKS | E10: CDT | G10: MGY | I10: LHR | K10: GST | M10: NPI | Q10: SVE | S10: LCI
B11: 1 | C11: - | I11: - | K11: PM | Q11: N | R11: RJF | S11: -
B12: 2 | C12: - | I12: AM | J12: 7h RTT- | K12: N | L12: PM | Q12: - | S12: -
A13: J | B13: 3 | C13: - | I13: AM | K13: N | L13: PM | Q13: - | S13: -
A14: A | B14: 4 | C14: - | I14: AM | K14: N | L14: PM | Q14: - | S14: -
A15: N | B15: 5 | C15: AM | I15: PM | J15: N | K15: - | Q15: 6h-14h | R15: VA | S15: AM
A16: V | B16: 6 | C16: AM | I16: PM | J16: N | K16: - | Q16: 6h-14h | R16: RTT | S16: AM
A17: I | B17: 7 | C17: PM | D17: 1h RHS | I17: N | K17: AM | Q17: 6h-14h | R17: RJF | S17: PM
A18: E | B18: 8 | C18: PM | I18: N | K18: AM | Q18: - | S18: PM
A19: R | B19: 9 | C19: N | D19: VA | I19: - | K19: PM | Q19: - | S19: N
B20: 10 | C20: N | I20: - | K20: PM | Q20: - | S20: N
B21: 11 | C21: N | I21: - | K21: PM | Q21: - | S21: N
B22: 12 | C22: - | I22: - | K22: N | L22: PM | Q22: AM | S22: -
B23: 13 | C23: - | I23: - | K23: N | L23: PM | Q23: AM | S23: -
A24: 2 | B24: 14 | C24: AM | D24: RHS | I24: 6h-14h | J24: D-F | K24: - | Q24: PM | R24: 4h RTT | S24: F | T24: 2h +FT
A25: 0 | B25: 15 | C25: AM | I25: 6h-14h | J25: CP | K25: - | Q25: D-F | R25: 1/2VA | S25: AM
A26: 2 | B26: 16 | C26: PM | I26: 6h-14h | J26: CP | K26: AM | Q26: N | S26: PM
A27: 6 | B27: 17 | C27: PM | D27: 8h -FT | I27: - | K27: AM | Q27: N | S27: PM
B28: 18 | C28: PM | I28: - | K28: AM | Q28: N | S28: PM
B29: 19 | C29: N | I29: AM | K29: PM | Q29: - | S29: N | T29: Abs
B30: 20 | C30: N | D30: VA | I30: DS | J30: 2h rhs | K30: PM | Q30: - | S30: N | T30: Abs
B31: 21 | C31: - | I31: 10h-22h | J31: 4h +FT | K31: N | L31: 20h15-06h | Q31: AM | S31: DS-CE | T31: Abs
B32: 22 | C32: - | I32: PM | J32: meunerie | K32: N | L32: RJF | Q32: AM | S32: - | T32: Abs
B33: 23 | C33: AM | I33: N | J33: meunerie | K33: - | Q33: PM | R33: 1/2VA | S33: AM | T33: Abs
B34: 24 | C34: AM | I34: N | K34: - | Q34: PM | R34: DTT | S34: AM
B35: 25 | C35: AM | I35: N | K35: - | Q35: PM | S35: AM
B36: 26 | C36: PM | I36: - | K36: - | Q36: N | S36: PM
B37: 27 | C37: PM | D37: chaudières | I37: - | K37: - | Q37: N | S37: PM
B38: 28 | C38: N | D38: 1h rhs | I38: AM | J38: D-CPPT | K38: 6h-14h | L38: VA | Q38: - | S38: N
B39: 29 | C39: N | D39: VA | I39: AM | J39: 1/2VA | K39: 6h-14h | L39: VA | Q39: - | S39: N
B40: 30 | C40: - | I40: PM | J40: N | K40: 6h-14h | L40: RTT | Q40: AM | S40: -
B41: 31 | C41: - | I41: PM | J41: N | K41: - | Q41: AM | R41: 2h RTT | S41: -
B42: 1 | C42: - | D42: AM | I42: N | J42: 22h-10h | K42: - | Q42: AM | S42: -
...

Sheet Step
A1: Opérateurs STEP - 2026 | F1: Date de dernière mise à jour
F2: =Shift1!O2 -> 46295.595
C4: VA | D4: Vacances annuelles | I4: xxx | J4: Congé accordé sous restriction - Rappelable | P4: CP | Q4: Congé Parental
C5: RTT | D5: Récup. temps de travail | I5: R | J5: Remplacement | P5: CSS | Q5: Congé sans solde
C6: RHS | D6: Récup. heures supplémentaires | I6: Abs. | J6: Absence - Maladie
C7: RJF | D7: Récup. Jour férié | I7: DS | J7: Délégation syndicale
C10: CAN | E10: PDE
B11: 1 | C11: AM | E11: -
B12: 2 | C12: AM | D12: 1h RTT- | E12: -
A13: J | B13: 3 | C13: - | E13: AM | F13: 6h-14h
A14: A | B14: 4 | C14: - | E14: AM
A15: N | B15: 5 | C15: AM | D15: CP | E15: AM
A16: V | B16: 6 | C16: AM | D16: RTT- | E16: AM
A17: I | B17: 7 | C17: AM | D17: RTT- | E17: AM | F17: 0,25h RHS
A18: E | B18: 8 | C18: - | E18: AM
A19: R | B19: 9 | C19: - | E19: AM
B20: 10 | C20: AM | E20: -
B21: 11 | C21: AM | E21: -
B22: 12 | C22: AM | D22: F | E22: AM | F22: F
B23: 13 | C23: AM | E23: AM
A24: 2 | B24: 14 | C24: AM | D24: F | E24: AM
A25: 0 | B25: 15 | C25: AM | D25: 1h RTT | E25: -
A26: 2 | B26: 16 | C26: AM | E26: -
A27: 6 | B27: 17 | C27: - | E27: AM
B28: 18 | C28: - | E28: AM
B29: 19 | C29: AM | D29: CP | E29: AM | F29: 2h +FT
B30: 20 | C30: AM | E30: AM | F30: 1h rhs
B31: 21 | C31: AM | D31: F | E31: AM
B32: 22 | C32: - | E32: AM
B33: 23 | C33: - | E33: AM | F33: 1h +FT
B34: 24 | C34: AM | E34: -
B35: 25 | C35: AM | E35: -
B36: 26 | C36: AM | E36: AM
B37: 27 | C37: AM | E37: AM
B38: 28 | C38: AM | E38: AM | F38: Abs
B39: 29 | C39: AM | E39: -
B40: 30 | C40: AM | E40: -
B41: 31 | C41: - | E41: AM | F41: 1h rhs
B42: 1 | C42: - | E42: AM | F42: 1h -FT
B43: 2 | C43: AM | D43: CP | E43: AM
...

Sheet Contremaître
A1: Contremaîtres de Production | F1: Date de dernière mise à jour | K1: CP | L1: Congé Parental
F2: =Shift1!O2 -> 46295.595 | K2: CSS | L2: Congé sans solde
A4: VA | B4: Vacances annuelles | G4: xxx | H4: Congé accordé sous restriction - Rappelable | O4: R-CM | P4: Remplacement Contremaître
A5: RTT | B5: Récup. temps de travail | G5: R | H5: Remplacement
A6: RHS | B6: Récup. heures supplémentaires | G6: Abs. | H6: Absence - Maladie
A7: RJF | B7: Récup. Jour férié | G7: DS | H7: Délégation syndicale
C9: 1 | E9: 2 | G9: 3 | I9: 4 | K9: 5 | M9: 6 | O9: 1 | Q9: 2 | S9: 3 | U9: 4 | W9: 5 | Y9: 6
C10: YPE | E10: GPS | G10: ATA | I10: AFA | K10: VBN | M10: FLI | O10: =Shift1!C10 -> VGG | Q10: =Shift1!E10 -> 0 | S10: =Shift1!G10 -> JBI | U10: =Shift1!I10 -> YBT | W10: =Shift1!K10 -> ATR | Y10: =Shift1!M10 -> FPA
B11: 1 | C11: - | E11: N | F11: 8h -FT | G11: - | I11: AM | K11: N | L11: R-CM | M11: D | N11: CP | O11: - | S11: - | U11: AM | V11: Abs | W11: PM | X11: 8h -FT | Y11: H. flott. | Z11: 8h -FT
B12: 2 | C12: - | E12: - | G12: AM | I12: PM | J12: RTT- | K12: - | M12: D | N12: CP | O12: H. flott | P12: RTT | S12: AM | T12: RHS | U12: PM | V12: Abs | W12: N | X12: R-CM | Y12: H. flott. | Z12: 4h RTT-
A13: J | B13: 3 | C13: - | E13: - | G13: AM | I13: PM | K13: - | M13: - | O13: - | S13: AM | U13: PM | V13: Abs | W13: N | X13: R-CM | Y13: - | Z13: 4h RTT
A14: A | B14: 4 | C14: - | E14: - | G14: AM | I14: PM | K14: - | M14: - | O14: - | S14: AM | T14: poly. Arr. | U14: PM | V14: Abs | W14: N | X14: R-CM | Y14: -
A15: N | B15: 5 | C15: 7h-15h | D15: N | E15: 7h-15h | G15: PM | I15: N | J15: RTT- | K15: 7h-15h | L15: CP | M15: AM | N15: Abs | O15: H. flott. | S15: PM | T15: RTT - | U15: N | V15: Abs | W15: - | Y15: AM | Z15: R-CM
A16: V | B16: 6 | C16: 7h-15h | D16: N | E16: 7h-15h | G16: PM | I16: D | J16: 2h RHS | K16: 7h-15h | L16: CP | M16: AM | N16: Abs | O16: H. flott. | P16: 1h RHS | S16: PM | T16: poly. Arr. | U16: N | V16: Abs | W16: - | Y16: AM | Z16: R-CM
A17: I | B17: 7 | C17: 7h-15h | D17: CP | E17: 7h-15h | F17: VA | G17: N | H17: RHS | I17: SD26 | J17: 6h +FT | K17: 7h-15h | L17: CP | M17: PM | N17: Abs | O17: H. flott. | P17: R-CM | S17: N | T17: R-CM | U17: - | V17: Abs | W17: R-CM | X17: 2h RTT- | Y17: PM | Z17: R-CM
A18: E | B18: 8 | C18: 7h-15h | E18: - | F18: SD26 | G18: N | H18: RHS | I18: SD26 | J18: 8h +FT | K18: - | M18: PM | N18: Abs | O18: H. flott. | P18: R-CM | S18: N | T18: R-CM | U18: - | V18: Abs | W18: AM | X18: VA | Y18: PM | Z18: R-CM
A19: R | B19: 9 | C19: 7h-15h | D19: VA | E19: - | F19: SD26 | G19: - | I19: AM | J19: SD26 | K19: - | M19: N | N19: Abs | O19: H. flott. | P19: RJF | S19: - | U19: AM | V19: Abs | W19: PM | X19: R-CM | Y19: N | Z19: R-CM
B20: 10 | C20: - | E20: - | G20: - | I20: AM | K20: - | M20: N | N20: Abs | O20: - | S20: - | T20: 4h +FT | U20: AM | V20: Abs | W20: PM | X20: R-CM | Y20: N | Z20: R-CM
B21: 11 | C21: - | E21: - | G21: - | I21: AM | K21: - | M21: N | N21: Abs | O21: - | S21: - | U21: AM | V21: Abs | W21: PM | X21: R-CM | Y21: N | Z21: R-CM
B22: 12 | C22: AM | D22: N | E22: 7h-15h | F22: PM | G22: 7h-15h | H22: TP | I22: PM | J22: SD26 | K22: 7h-15h | M22: - | O22: AM | P22: poly-arr | S22: AM | T22: R-CM | U22: PM | V22: Abs | W22: N | Y22: -
B23: 13 | C23: AM | D23: N | E23: 7h-15h | F23: PM | G23: 7h-15h | H23: TP | I23: PM | J23: SD26 | K23: AM | L23: R-CM | M23: - | O23: AM | P23: Abs | S23: 7h-15h | T23: 1h rhs | U23: PM | V23: Abs | W23: N | X23: R-CM | Y23: - | Z23: 2h +FT
A24: 2 | B24: 14 | C24: N | D24: 3h RTT | E24: 7h-15h | F24: 1h RTT | G24: 7h-15h | H24: TP | I24: N | J24: 1h +FT | K24: 7h-15h | L24: F | M24: AM | N24: eval | O24: PM | P24: Abs | S24: 14h-01h | T24: R-CM | U24: PM | V24: Abs | W24: - | Y24: AM | Z24: R-CM
